Workbook

Sheet RESUMEN CONSOLIDADO
K3: NUMERAL | L3: CUMPLIMIENTO
K4: =CONTEXTO!$S$6 -> 4. CONTEXTO DE LA ORGANIZACIÓN | L4: =CONTEXTO!T6 -> 0.9375
K5: =LIDERAZGO!S7 -> 5. LIDERAZGO | L5: =LIDERAZGO!T7 -> 0.87962963
K6: =PLANIFICACIÓN!X13 -> 6. PLANIFICACIÓN | L6: =PLANIFICACIÓN!Y13 -> 0.88411458
K7: =APOYO!V13 -> 7. APOYO | L7: =APOYO!W13 -> 0.91893939
K8: =OPERACIÓN!S5 -> 8.OPERACIÓN | L8: =OPERACIÓN!T5 -> 0.71875
K9: ='EVALUACIÓN DEL DESEMPEÑO'!S9 -> 9 EVALUACIÓN DEL DESEMPEÑO | L9: ='EVALUACIÓN DEL DESEMPEÑO'!T9 -> 0.94285714
K10: =MEJORA!P7 -> 10. MEJORA | L10: =MEJORA!Q7 -> 0.66666667

Sheet RESUMEN POR CAPÍTULO

Sheet CONTEXTO
B2: 4. CONTEXTO DE LA ORGANIZACIÓN | C2: NO APLICA | D2: COMPLETO | E2: PARCIAL | F2: NINGUNO | G2: QUÉ TIENE? | H2: QUE NOS FALTA | I2: ACCIONES | J2: FECHA | K2: RESPONSABLE | S2: 4.1 Comprensión de la organización y de su contexto | T2: =D3 -> 0.75
B3: 4.1 Comprensión de la organización y de su contexto | D3: =((D7*1)+(E7*0.5)+(F7*0))/2 -> 0.75 | S3: 4.2 Comprensión de las necesidades y expectativas de las partes interesadas | T3: =D8 -> 1
B4: La organización debe determinar: | S4: 4.3 Determinación del alcance del sistema de gestión ambiental | T4: =D15 -> 1
B5: Las cuestiones externas e internas que son pertinentes para su propósito y que afectan a su capacidad para lograr los resultados previstos de su sistema de gestión ambiental | E5: X | G5: Contexto estrategico. | H5: Recibir información de todos los procesos del analisis DOFA | I5: Actualizar contexto teniendo en cuenta el taller de DOFA enviado por Gerencia | J5: 44232 | K5: Angelica Paez | S5: 4.4 Sistema de Gestión Ambiental | T5: =D25 -> 1
B6: Realizar el seguimiento y la revisiòn de la informaciòn sobre estas cuestiones internas y externas | D6: X | G6: Seguiminetos anuales. | I6: Realizar año 2021. Esperamos la actualización . | J6: 44236 | K6: Angelica Paez | S6: =B2 -> 4. CONTEXTO DE LA ORGANIZACIÓN | T6: =AVERAGE(T2:T5) -> 0.9375
D7: =COUNTIF(D5:D6,"X") -> 1 | E7: =COUNTIF(E5:E6,"X") -> 1 | F7: =COUNTIF(F5:F6,"X") -> 0
B8: 4.2 Comprensión de las necesidades y expectativas de las partes interesadas | D8: =((D14*1)+(E14*0.5)+(F14*0))/4 -> 1
B9: La organización debe determinar:
B10: a. Las partes interesadas que son pertinentes al sistema de gestión ambiental; | D10: X
B11: b.Las necesidades y expectativas pertinentes (es decir, requisitos) de estas partes interesadas; | D11: X | G11: Matriz de necesidades y expectativas de partes interesadas | I11: Verificar Plan de ayuda mutua
B12: c. cuáles de estas son requisitos legales y otros requisitos. | D12: X
B13: La organización debe realizar el seguimiento y la revisión de la información sobre estas partes interesadas y sus requisitos pertientes. | D13: X
D14: =COUNTIF(D10:D13,"X") -> 4 | E14: =COUNTIF(E10:E13,"X") -> 0 | F14: =COUNTIF(F10:F13,"X") -> 0
B15: 4.3 Determinación del alcance del sistema de gestión ambiental | D15: =((D24*1)+(E24*0.5)+(F24*0))/7 -> 1
B16: Cuando se determina este alcance, la organización debe considerar:
B17: a. Las cuestiones externas e internas referidas en el apartado 4.1; | D17: X
B18: b. Los requisitos legales y otros requisitos a que se hace referencia en el apartado 4.2; | D18: X
B19: c. Las unidades, funciones y límites físicos de la organización; | D19: X
B20: d. Sus actividades, productos y servicios; | D20: X
B21: e. Su autoridad y capacidad para ejercer control e influencia. | D21: X
B22: El alcance debe estar disponible y mantenerse como información documentada estableciendo: | D22: X
B23: »Todas las actividades, productos y servicios cubiertos por el sistema de gestión ambiental; | D23: X
D24: =COUNTIF(D17:D23,"X") -> 7 | E24: =COUNTIF(E17:E23,"X") -> 0 | F24: =COUNTIF(F17:F23,"X") -> 0
B25: 4.4 Sistema de Gestión Ambiental | D25: =((D29*1)+(E29*0.5)+(F29*0))/2 -> 1
B26: Para lograr los resultados previstos, incluida la mejora de su desempeño ambiental, la organización debe
B27: establecer, implementar, mantener y mejorar continuamente su sistema de gestión ambiental incluyendo los procesos e interacciones necesarias. | D27: X
B28: Considerar los apartados 4.1 y 4.2 | D28: X
D29: =COUNTIF(D27:D28,"X") -> 2 | E29: =COUNTIF(E27:E28,"X") -> 0 | F29: =COUNTIF(F27:F28,"X") -> 0

Sheet LIDERAZGO
B2: 5. LIDERAZGO | C2: NO APLICA | D2: COMPLETO | E2: PARCIAL | F2: NINGUNO | G2: QUÉ TIENE? | H2: QUÉ NOS FALTA | I2: ACCIONES | J2: FECHA | K2: RESPONSABLE
B3: 5.1 Liderazgo y compromiso | D3: =((D14*1)+(E14*0.5)+(F14*0))/9 -> 0.88888889
B4: La alta dirección debe demostrar liderazgo y compromiso con respecto al Sistema de gestión ambiental | S4: =B3 -> 5.1 Liderazgo y compromiso | T4: =D3 -> 0.88888889
B5: a) asumiendo la responsabilidad y la obligaciòn de rendir cuentas con relación a la eficacia del sistema de gestión ambiental; | E5: X | G5: Comité gerencial | H5: Incluir la parte ambiental y SST en el comité de gerencia | I5: Revisión y aprobaci´n de gerencia | J5: 44242 | K5: Gerencia | S5: =B15 -> 5.2 Política Ambiental | T5: =D15 -> 1
B6: b) asegurando que se establezcan la política ambiental y los objetivos ambientales, y que éstos sean compatibles con la dirección estratégica y el contexto de la organización; | D6: X | G6: Politica integrada, Programas ambientales | S6: =B27 -> 5.3. Roles, responsabilidades y autoridades en la organización | T6: =D27 -> 0.75
B7: c) asegurándose de la integración de los requisitos del Sistema de Gestión ambiental en los procesos de negocios de la organización | D7: X | G7: Todos los procesos entrads y salidas | S7: =B2 -> 5. LIDERAZGO | T7: =AVERAGE(T4:T6) -> 0.87962963
B8: d) Asegurando que los recursos necesarios para el sistema de gestión ambiental estén disponibles | D8: X | G8: Presupuesto
B9: e) comunicando la importancia de una gestión ambiental eficaz y conforme con los requisitos del sistema de gestión ambiental | D9: X | G9: Reinducción. Actas
B10: f) asegurándose de que el sistema de gestión ambiental logre los resultados previstos; | E10: X | G10: Programas con sus indicadores | I10: Incluir en el acta de inducción la parte ambiental
B11: g) dirigiendo y apoyando a las personas, para contribuir a la eficacia del sistema de gestión ambiental; | D11: X | G11: Sensibiliacioes, capañas correos y whatsapp.
B12: h) Promover la mejora continua; | D12: X | G12: Proceso y procedimiento
B13: i) Apoyando otros roles pertinentes de la dirección, para demostrar su liderazgo aplicado a sus áreas de responsabilidad. | D13: X | G13: Descripciones de cargo | I13: Verificar descripció de cargo | J13: Inmediato | K13: Mariana Sarabia
D14: =COUNTIF(D5:D13,"X") -> 7 | E14: =COUNTIF(E5:E13,"X") -> 2 | F14: =COUNTIF(F5:F13,"X") -> 0
B15: 5.2 Política Ambiental | D15: =((D26*1)+(E26*0.5)+(F26*0))/8 -> 1
B16: La alta dirección debe establecer, implementar y mantener una política ambiental que, dentro del alcance definido de su sistema de gestión ambiental:
B17: a) sea apropiada al propósito y contexto de la organización, incluida la naturaleza, magnitud e impactos ambientales de sus actividades, productos y servicios; | D17: X | G17: Politica Integrada, aprobada por Gerencia
B18: b) proporcione un marco de referencia para el establecimiento de los objetivos ambientales; | D18: X | G18: Es el marco de referencia para los objetivos ambientales.
B19: c) incluya un compromiso con la protección del medio ambient, incluida la prevención de la contaminación, y otros compromisos específicos pertinentes al contexto de la organización; | D19: X | G19: Inluye la prevencion ambiental
B20: d) incluya un compromiso de cumplir con los requisitos legales y otros requisitos; | D20: X | G20: En ella se encuentra el compromiso de cumplir requisitos legales.
B21: e) incluya un compromiso de mejora continua del seistema de gestión ambiental para la mejora del desempeño ambiental. | D21: X | G21: Se encuentra el compromiso de mejora continua.
B22: La política ambiental debe:
B23: » mantenerse como información documentada; | D23: X | G23: Se encuentra documentada y aprobada por gerencia
B24: » comunicarse dentro de la organización; | D24: X | G24: Se encuentra en el Manual del Sistema de Gestión y la cartelera . Además se entrega en la inducción y reinducción
B25: » estar disponible para las partes interesadas. | D25: X | G25: Cuando las partes interesads la requiera.
D26: =COUNTIF(D17:D25,"X") -> 8 | E26: =COUNTIF(E17:E25,"X") -> 0 | F26: =COUNTIF(F17:F25,"X") -> 0
B27: 5.3. Roles, responsabilidades y autoridades en la organización | D27: =((D32*1)+(E32*0.5)+(F32*0))/2 -> 0.75
B28: La alta dirección debe asegurarse de que las responsabilidades y autoridades para los roles pertinentes se asignen, se comuniquen y se entiendan dentro de la organización.
B29: La alta dirección debe asignar la responsabilidad y autoridad para:
B30: a) asegurarse de que el sistema de gestión ambiental es conforme con los requisitos de esta Norma Internacional; | D30: X | G30: Asignada la Cooedinadora HSEQ
B31: b) informar en particular a la alta dirección el desempeño del sistema de gestión ambiental, incluyendo su desempeño | E31: X | G31: Comité Gerencial | H31: Hacer la revisión por la Dirección | I31: Programar y hacer la revisión por la dirección | J31: 44255
D32: =COUNTIF(D30:D31,"X") -> 1 | E32: =COUNTIF(E30:E31,"X") -> 1 | F32: =COUNTIF(F30:F31,"X") -> 0
H39: a<

Sheet PLANIFICACIÓN
B2: 6. PLANIFICACIÓN | C2: NO APLICA | D2: COMPLETO | E2: PARCIAL | F2: NINGUNO | G2: QUÉ TIENE? | H2: QUE NOS FALTA | I2: ACCIONES | J2: FECHA | K2: RESPONSABLE
B3: 6.1 Acciones para abordar riesgos y oportunidades | D3: =AVERAGE(D4,D14,D22,D28) -> 0.86458333
B4: 6.1.1 Generalidades | D4: =((D13*1)+(E13*0.5)+(F13*0))/8 -> 0.875
B5: La organización debe establecer, implementar y mantener los procesos necesarios para cumplir con los requisitos de los apartados 6.1.1 a 6.1.4. | D5: X | G5: 14 Procesos determinados | X5: =B3 -> 6.1 Acciones para abordar riesgos y oportunidades | Y5: =D3 -> 0.86458333
B6: Al planificar el sisteme de gestión ambiental la organización debe considerar: a) las cuestiones referidas en el apartado 4.1; b) los requisitos referidos en el apartado 4.2; c) el alcance de su sistema de gestión ambiental; | D6: X | G6: Contexto estrategico | H6: Revisarlo con el taller que se está realizando con los responsables de porceso | I6: Realizar año 2021. Esperamos la actualización . | J6: 44236 | K6: Angelica Paez | X6: =B4 -> 6.1.1 Generalidades | Y6: =D4 -> 0.875
B7: Determina los riesgos y oportunidades relacionados con sus: aspectos ambientales; requisitos legales y otros requisitos; »otras cuestiones y requisitos identificados en los apartados 4.1 4.2 | E7: X | G7: Matrices de riesgo y oportunidades | H7: Revisar las matrices de riesgos y oportunidades | I7: Actualizar matrices de riesgos y oporyunidades | J7: 44283 | K7: Lideres de Procesos/Angelica Paez | X7: =B14 -> 6.1.2 Aspectos ambientales | Y7: =D14 -> 0.91666667
B8: Asegura que el sistema de gestión ambiental puede lograr los resultados previstos | D8: X | X8: =B22 -> 6.1.3 Requisitos legales y otros requisitos | Y8: =D22 -> 1
B9: Prevenir o reducir los efectos no deseados. | D9: X | X9: =B28 -> 6.1.4 Planificación de acciones | Y9: =D28 -> 0.66666667
B10: Lograr la mejora continua | D10: X | X10: =B33 -> 6.2 Objetivos ambientales y planificación para lograrlos | Y10: =D33 -> 0.91666667
B11: Dentro del alcance del sistema de gestión ambiental, la organización determinara las situaciones de emergencia potenciales, incluidas las que pueden tener un impacto ambiental | E11: X | G11: Plan de emergencia | H11: Verificar parte ambiental. Se esta realizando con el Ing Eudaldo Natera | I11: Actualizar en caso necesario | J11: 44255 | K11: Angelica Paez | X11: =B34 -> 6.2.1 Objetivos ambientales | Y11: =D34 -> 0.83333333
B12: La organización mantiene la información documentada de sus riesgos y oportunidades que son necesario abordar | D12: X | G12: Matrices de riesgos | X12: =B43 -> 6.2.2 Planificación de acciones para lograr los objetivos ambientales | Y12: =D43 -> 1
D13: =COUNTIF(D5:D12,"X") -> 6 | E13: =COUNTIF(E5:E12,"X") -> 2 | F13: =COUNTIF(F5:F12,"X") -> 0 | X13: =B2 -> 6. PLANIFICACIÓN | Y13: =AVERAGE(Y5:Y12) -> 0.88411458
B14: 6.1.2 Aspectos ambientales | D14: =((D21*1)+(E21*0.5)+(F21*0))/6 -> 0.91666667
B15: Dentro del alcance definido del sistema de gestión ambiental, la organización determinara los aspectos ambientales de sus actividades, productos y servicios | E15: X | G15: Matriz de aspectos e impactos ambientales. | H15: Incluir Compras, para cumplir con el Ciclo de vida | I15: Actualizar matriz de aspectos e impactos ambientales | J15: 44255 | K15: Angelica Paez
B16: Cuando se determinan los aspectos ambientales, la organización tiene en cuenta los cambios, incluidos los desarrollos nuevos o planificados, y las actividades, productos y servicios nuevos o modificados | D16: X | G16: Procedimiento de Gestión de cambios
B17: La organización tiene en cuenta las condiciones anormales y las situaciones de emergencia razonablemente previsibles | D17: X | G17: Matriz de aspectos e impactos ambientales.
B18: La organización determina aquellos aspectos que tengan o puedan tener un impacto ambiental significativo, es decir, los aspectos ambientales significativos, mediante el uso de criterios establecidos? | D18: X | G18: Matriz de aspectos e impactos ambientales.
B19: La organización determinara aquellos aspectos que tengan o puedan tener un impacto ambiental significativo | D19: X | G19: Matriz de aspectos e impactos ambientales.
B20: La organización mantiene información documentada de sus aspectos ambientales e impactos ambientales asociados, criterios usados para determinar sus aspectos ambientales significativos y aspectos ambientales significativos | D20: X | G20: Matriz de aspectos e impactos ambientales.
D21: =COUNTIF(D15:D20,"X") -> 5 | E21: =COUNTIF(E15:E20,"X") -> 1 | F21: =COUNTIF(F15:F20,"X") -> 0
B22: 6.1.3 Requisitos legales y otros requisitos | D22: =((D27*1)+(E27*0.5)+(F27*0))/4 -> 1
B23: a) determinar y tener acceso a los requisitos legales y otros requisitos relacionados con sus aspectos ambientales; | D23: X | G23: Matriz de requisitos legales
B24: b) determinar cómo estos requisitos legales y otros requisitos se aplican a la organización; | D24: X | G24: Matriz de requisitos legales
B25: c) tener en cuenta estos requisitos legales y otros requisitos cuando se establezca, implemente, mantenga y mejore continuamente su sistema de gestión ambiental. | D25: X | G25: Matriz de requisitos legales
B26: La organización mantiene información documentada de sus requisitos legales y otros requisitos | D26: X | G26: Matriz de requisitos legales
D27: =COUNTIF(D23:D26,"X") -> 4 | E27: =COUNTIF(E23:E26,"X") -> 0 | F27: =COUNTIF(F23:F26,"X") -> 0
B28: 6.1.4 Planificación de acciones | D28: =((D32*1)+(E32*0.5)+(F32*0))/3 -> 0.66666667
B29: a) La organización debe planificar la toma de acciones para abordar sus aspectos ambientales significativos; requisitos legales y otros requisitos; riesgos y oportunidades identificados en el apartado 6.1.1. | E29: X | G29: Matriz de Aspectos, Riesgos y Requisitos legales.
B30: b) Debe planificar la manera de integrar e interpretar las acciones en los procesos de su sistema de gestión ambiental, planificar la manera de evaluar la eficacia de estas acciones. | E30: X | G30: Matriz de Aspectos, Riesgos y Requisitos legales.
B31: La organización debe considerar sus opciones tecnológicas y sus requisitos financieros, operacionales y de negocio. | D31: X | G31: Presupuesto del SIG
D32: =COUNTIF(D29:D31,"X") -> 1 | E32: =COUNTIF(E29:E31,"X") -> 2 | F32: =COUNTIF(F29:F31,"X") -> 0
B33: 6.2 Objetivos ambientales y planificación para lograrlos | D33: =AVERAGE(D34,D43) -> 0.91666667
B34: 6.2.1 Objetivos ambientales | D34: =((D42*1)+(E42*0.5)+(F42*0))/6 -> 0.83333333
B35: La organización establece objetivos ambientales para las funciones y niveles pertinentes, teniendo en cuenta los aspectos ambientales significativos de la organización y sus requisitos legales y otros requisitos asociados y considerando sus riesgos y oportunidades. Los objetivos ambientales deben:
B36: a) Los objetivos ambientales son coherentes con la política ambiental; | D36: X | G36: Programas ambientales.
B37: b) Los objetivos ambientales son medibles (si es factible); | D37: X
B38: c) Los objetivos ambientales son objeto de seguimiento | D38: X
B39: d) Los objetivos ambietales son comunicados en la organización | D39: X
B40: e) Los objetivos ambientales son actualizados según correspondan | D40: X | G40: Todos los años.
B41: La organización conserva información documentada sobre los objetivos ambientales
...

Sheet APOYO
B2: 7. APOYO | C2: NO APLICA | D2: COMPLETO | E2: PARCIAL | F2: NINGUNO | G2: QUÉ TIENE? | H2: QUE NOS FALTA | I2: ACCIONES | J2: RESPONSABLES | K2: FECHA | V2: =B3 -> 7.1 Recursos | W2: =D3 -> 1
B3: 7.1 Recursos | D3: =((D5*1)+(E5*0.5)+(F5*0))/1 -> 1 | V3: =B6 -> 7.2 Competensia | W3: =D6 -> 0.9
B4: Alutrafic determina y proporciona los recursos necesarios para el establecimiento, implementación, mantenimiento y mejora continua del sistema de gestión ambiental | D4: X | V4: =B14 -> 7.3 Toma de conciencia | W4: =D14 -> 0.875
D5: =COUNTIF(D4,"X") -> 1 | E5: =COUNTIF(E4,"X") -> 0 | F5: =COUNTIF(F4,"X") -> 0 | V5: =B21 -> 7.4 Comunicación | W5: =D21 -> 0.83333333
B6: 7.2 Competensia | D6: =((D13*1)+(E13*0.5)+(F13*0))/5 -> 0.9 | V6: =B22 -> 7.4.1 Generalidades | W6: =D22 -> 1
B7: La organización debe: | V7: =B27 -> 7.4.2 Comunicación Interna | W7: =D27 -> 0.5
B8: Alutrafic determina la competencia necesaria de las personas que realizan trabajos bajo su control, que afecte a su desempeño ambiental y su capacidad para cumplir sus requisitos legales y otros requisitos. | D8: X | G8: Descripciones de Cargo y Procedimientos | V8: =B31 -> 7.4.3 Comunicación externa | W8: =D31 -> 1
B9: Alutrafic asegura de que estas personas sean competentes, con base en su educación, formación o experiencia apropiadas. | D9: X | V9: =B34 -> 7.5 INFORMACIÓN DOCUMENTADA | W9: =D34 -> 1
B10: Alutrafic determina las necesidades de formación asociadas con sus aspectos ambientales y su sistema de gestión ambiental. | E10: X | H10: Verificar las descripciones de cargo. | I10: Actualizar descripciones de cargo en caso necesario | J10: Responsables de Procesos/Angelica Paez | V10: =B35 -> 7.5.1 Generalidades. | W10: =D22 -> 1
B11: Alutrafic determina cuando sea aplicable, tomar acciones para adquirir la competencia necesaria y evaluar la eficacia de las acciones tomadas? | D11: X | G11: Procedimiento de Talento Humano | V11: =B39 -> 7.5.2 Creación y actualización | W11: =D39 -> 1
B12: ¿La organización debe conservar información documentada apropiada, como evidencia de la competencia? | D12: X | V12: =B42 -> 7.5.3 Control de la información documentada | W12: =D42 -> 1
D13: =COUNTIF(D8:D12,"X") -> 4 | E13: =COUNTIF(E8:E12,"X") -> 1 | F13: =COUNTIF(F8:F12,"X") -> 0 | V13: =B2 -> 7. APOYO | W13: =AVERAGE(W2:W12) -> 0.91893939
B14: 7.3 Toma de conciencia | D14: =((D20*1)+(E20*0.5)+(F20*0))/4 -> 0.875
B15: La organización debe asegurarse de que las personas que realicen el trabajo bajo el control de la organización tomen conciencia
B16: a. La política ambiental | D16: X | G16: Programa de Capacitación
B17: b. los aspectos ambientales significativos y los impactos ambientales reales o potenciales relacionados, asociados con su trabajo; | E17: X | G17: Sensibilización
B18: c. su contribución a la eficacia del sistema de gestión ambiental, incluidos los beneficios de una mejora del desempeño ambiental; | D18: X | G18: Sensibilización
B19: d. las implicaciones de no satisfacer los requisitos del sistema de gestión ambiental, incluido el incumplimiento de los requisitos legales y otros requisitos de la organización. | D19: X | G19: Sensibilización
D20: =COUNTIF(D16:D19,"X") -> 3 | E20: =COUNTIF(E16:E19,"X") -> 1 | F20: =COUNTIF(F16:F19,"X") -> 0
B21: 7.4 Comunicación | D21: =AVERAGE(D22,D27,D31) -> 0.83333333
B22: 7.4.1 Generalidades | D22: =((D26*1)+(E26*0.5)+(F26*0))/3 -> 1
B23: La organización debe establecer, implementar y mantener los procesos necesarios para las comunicaciones internas y externas pertinentes al sistema de gestión ambiental, que incluyan: a) que comunicar; b) cuándo counicar; c) a quién comunicar; d) cómo comunicar | D23: X | G23: Están en cada proceso y tambien tenemos una matriz de comunicaciones | H23: Verificar lascomunicaciones | I23: Actualizar procesos y matriz de comunicaciones en caso necesario | J23: Angelica Paez | K23: 44255
B24: Cuando establece los procesos de comunicación Alutrafic tiene en cuanta los requisitos legales y otros requisitos, asegura que la información ambiental comunicada sea coherente con la información generada dentro del sistema de gestión ambiental, a que sea fiable | D24: X
B25: La organización conserva la información documentada como evidencia de sus comunicaciones, según corresponda. | D25: X
D26: =COUNTIF(D23:D25,"X") -> 3 | E26: =COUNTIF(E23:E25,"X") -> 0 | F26: =COUNTIF(F23:F25,"X") -> 0
B27: 7.4.2 Comunicación Interna | D27: =((D30*1)+(E30*0.5)+(F30*0))/2 -> 0.5
B28: a) La organización comunica internamente la información pertinente del sistema de gestión ambiental entre los diversos niveles y funciones de la organización, incluidos los cambios en el sistema de gestión ambiental, según corresponda; | E28: X | G28: Se informa. Falta más frecuencia
B29: b) La organización asegura que sus procesos de comunicación permitan que las personas que realicen trabajos bajo control de la organización contribuyan a la mejora continua. | E29: X
D30: =COUNTIF(D28:D29,"X") -> 0 | E30: =COUNTIF(E28:E29,"X") -> 2 | F30: =COUNTIF(F28:F29,"X") -> 0
B31: 7.4.3 Comunicación externa | D31: =((D33*1)+(E33*0.5)+(F33*0))/1 -> 1
B32: La organización comunica externamente información pertinente al sistema de gestión ambiental, según se establezca en los procesos de comunicación de la organización | D32: X | G32: Cuando se haga necesario
D33: =COUNTIF(D32,"X") -> 1 | E33: =COUNTIF(E32,"X") -> 0 | F33: =COUNTIF(F32,"X") -> 0
B34: 7.5 INFORMACIÓN DOCUMENTADA | D34: =AVERAGE(D35,D39,D42) -> 1
B35: 7.5.1 Generalidades. | D35: =((D38*1)+(E38*0.5)+(F38*0))/2 -> 1
B36: El sistema de gestión ambiental debe incluir, información documentada requerida por esta Norma Internacional | D36: X | G36: Tenemos el Sistema Integrado, con accesos restringidos
B37: El sistema de gestión ambiental de la organización determina información documentada como necesaria para la eficacia del sistema de gestión ambiental | D37: X
D38: =COUNTIF(D36:D37,"X") -> 2 | E38: =COUNTIF(E36:E37,"X") -> 0 | F38: =COUNTIF(F36:F37,"X") -> 0
B39: 7.5.2 Creación y actualización | D39: =((D41*1)+(E41*0.5)+(F41*0))/1 -> 1
B40: Al crear y actualizar la información documentada, la organización se asegura de que lo siguiente sea apropiado:La identificación y descripción, el formato la revisión y aprobación | D40: X
D41: =COUNTIF(D40,"X") -> 1 | E41: =COUNTIF(E40,"X") -> 0 | F41: =COUNTIF(F40,"X") -> 0
...

Sheet OPERACIÓN
B2: 8.OPERACIÓN | C2: NO APLICA | D2: COMPLETO | E2: PARCIAL | F2: NINGUNO | G2: QUÉ TIENE? | H2: QUE NOS FALTA | I2: ACCIONES | J2: RESPONSABLES | K2: FECHA
B3: 8.1 Planificación y control operacional | D3: =((D12*1)+(E12*0.5)+(F12*0))/8 -> 0.8125 | S3: =B3 -> 8.1 Planificación y control operacional | T3: =D3 -> 0.8125
B4: La organización establece, implementa, controla y mantiene los procesos necesarios para satisfacer los requisitos del sistema de gestión ambiental | D4: X | G4: Los procesos del SIG | S4: =B13 -> 8.2 Preparación y respuesta ante emergencia | T4: =D13 -> 0.625
B5: La organización controla los cambios planificados y examinar las consecuencias de los cambios no previstos, tomando acciones para mitigar los efectos adversos, cuando sea necesario | D5: X | S5: =B2 -> 8.OPERACIÓN | T5: =AVERAGE(T3:T4) -> 0.71875
B6: La organización se asegura de que los procesos contratados externamente estén controlados o que se tenga influencia sobre ellos | D6: X
B7: a) La organización establece los controles, según corresponda, para asegurarse de que sus requisitos ambientales se aborden en el proceso de diseño y desarrollo del producto o servicio, considerando cada etapa de su ciclo de vida | E7: X | G7: Proceso y procedimiento de diseño | H7: Incluir ECODISEÑO. | I7: Actualizar Proceso, Procedimiento y aplicación | J7: Daniel | K7: 44255
B8: b) La organización determina sus requisitos ambientales para la compra de productos y servicios, según corresponda. | D8: X | G8: Evaluación y Selección de Proveedores
B9: c) La organización comunicar sus requisitos ambientales pertinentes a los proveedores externos, incluidos los contratistas | G9: Manual de Contratistas | H9: Verificar si tiene la parte ambiental | I9: Actualizar el Manual en Caso necesario | J9: Luis | K9: 44255
B10: d) La organización considera la necesidad de suministrar información acerca de los impactos ambientales potenciales significativos asociados con el transporte o la entrega, el uso, el tratamiento al fin de la vida útil y la disposición final de sus productos o servicios. | D10: X
B11: La organización mantiene la información documentada en la medida necesaria para tener la confianza en que los procesos se han llevado a cabo según lo planificado. | D11: X
D12: =COUNTIF(D4:D11,"X") -> 6 | E12: =COUNTIF(E4:E11,"X") -> 1 | F12: =COUNTIF(F4:F11,"X") -> 0
B13: 8.2 Preparación y respuesta ante emergencia | D13: =((D22*1)+(E22*0.5)+(F22*0))/8 -> 0.625
B14: La organización establece, implementa y mantiene los procesos necesarios acerca decómo prepararse y responder a situaciones potenciales de emergencia identificadas en el apartado 6.1.1 | D14: X | G14: Plan de Emergencia
B15: a) La organización está preprada para responder, mediante la planificación de acciones para prevenir o mitigar los impactos ambientales adversos provocados por situaciones de emergencia. | E15: X
B16: b) La organización responde a situaciones de emergencia reales | D16: X
B17: c) La organización toma acciones para prevenir o mitigar las consecuencias de las situaciones de emergencia, apropiadas a la magnitud de la emergencia y al impacto ambiental potencial. | E17: X | G17: Falta simulacro
B18: d) La organización toma acciones para prevenir o mitigar las consecuencias de las situaciones de emergencia, apropiadas a la magnitud de la emergencia y al impacto ambiental potencial | E18: X
B19: e) La rganización pone a prueba periodicamente las acciones de respuesta planificadas, cuando sea factible | E19: X | H19: Preparar simulacro ambiental | I19: Hacer el simulacro | J19: Angelica Paez | K19: 44285
B20: f) La organización proporciona información y formación pertinentes, con relación a la preparación y respuesta ante emergencias, según corresponda, a las partes interesadas pertinentes,incluidas las personas que trabajan bajo su control | E20: X
B21: La organización mantiene la información documentada en la medida necesaria para tener confianza en que los procesos se llevan a cabo de la manera planificada | E21: X
D22: =COUNTIF(D14:D21,"X") -> 2 | E22: =COUNTIF(E14:E21,"X") -> 6 | F22: =COUNTIF(F14:F21,"X") -> 0

Sheet EVALUACIÓN DEL DESEMPEÑO
B2: 9 EVALUACIÓN DEL DESEMPEÑO | C2: NO APLICA | D2: COMPLETO | E2: PARCIAL | F2: NINGUNO | G2: QUÉ TIENE? | H2: QUE NOS FALTA | I2: ACCIONES | J2: RESPONSABLE | K2: FECHA | S2: =B3 -> 9.1 Seguimiento, medición, análisis y evaluación | T2: =D3 -> 1
B3: 9.1 Seguimiento, medición, análisis y evaluación | D3: =AVERAGE(D4,D13) -> 1 | S3: =B4 -> 9.1.1 Generalidades | T3: =D4 -> 1
B4: 9.1.1 Generalidades | D4: =((D12*1)+(E12*0.5)+(F12*0))/6 -> 1 | S4: =B13 -> 9.1.2 Evaluación del cumplimiento | T4: =D13 -> 1
B5: La organización debe determinar: | S5: =B20 -> 9.2 Auditoría interna | T5: =D20 -> 1
B6: a) a qué es necesario hacer seguimiento y qué es necesario medir; | D6: X | G6: Programas ambientales | S6: =B21 -> 9.2.1 Generalidades | T6: =D21 -> 1
B7: b) los métodos de seguimiento, medición, análisis y evaluación, según sea aplicable, para asegurar resultados válidos; | D7: X | G7: Indicadores mensuales | S7: =B26 -> 9.2.2 Programa de auditoría interna | T7: =D26 -> 1
B8: c) Los criterios contra los cuales la organización evaluará su desempeño ambiental y los indicadores apropiados; | D8: X | G8: Se encuentran en cada programa | S8: =B33 -> 9.3 Revisión por la dirección | T8: =D33 -> 0.6
B9: d) cuándo se deben llevar a cabo el seguimiento y la medición; | D9: X | G9: Mensualmente | S9: =B2 -> 9 EVALUACIÓN DEL DESEMPEÑO | T9: =AVERAGE(T2:T8) -> 0.94285714
B10: e) cuándo se deben analizar y evaluar los resultados del seguimiento y la medición. | D10: X | G10: Mensualmente
B11: La organización debe asegurarse de que se usan y mantienen equipos de segumiento y medición calibrados o verificados, según corresponda. Deberá evaluar el desempeño ambiental y la eficacia del sistema de gestión ambiental. Asi como comunicar externa e internamente la información pertinente a su desempeño ambiental, según sus procesos de comunicación y como se exija en sus requisitos legales y otros requisitos. De igual forma debera conservar información documentada como evidencia del seguimiento, medición, análisis y la evaluación. | D11: X | G11: Son externos. Se les pide toda la información necesaria para demostrar cumplimiento.
D12: =COUNTIF(D6:D11,"X") -> 6 | E12: =COUNTIF(E6:E11,"X") -> 0 | F12: =COUNTIF(F6:F11,"X") -> 0
B13: 9.1.2 Evaluación del cumplimiento | D13: =((D19*1)+(E19*0.5)+(F19*0))/5 -> 1
B14: La organización debe establecer, implementar y mantener los procesos necesarios para evaluar el cumplimiento de sus requisitos legales y otros requisitos. La organización debe: | D14: X | G14: Cronograma de revisión
B15: a) determinar la frecuencia con la que se evaluará el cumplimiento; | D15: X | G15: Cronograma de revisión
B16: b) evaluar el cumplimiento y emprender las acciones que fueran necesarias; | D16: X | G16: Cronograma de revisión
B17: c) mantener el conocimiento y la comprensión de su estado de cumplimiento | D17: X | G17: Cronograma de revisión
B18: La organización debe conservar información documentada como evidencia de los resultados de la evaluación del cumplimiento. | D18: X | G18: matriz de requisitos legales.
D19: =COUNTIF(D14:D18,"X") -> 5 | E19: =COUNTIF(E14:E18,"X") -> 0 | F19: =COUNTIF(F14:F18,"X") -> 0
B20: 9.2 Auditoría interna | D20: =AVERAGE(D21,D26) -> 1
B21: 9.2.1 Generalidades | D21: =((D25*1)+(E25*0.5)+(F25*0))/2 -> 1
B22: La organización debe llevar a cabo auditorías internas a intervalos planificados, para proporcionar información acerca de si el sistema de gestión de la calidad:
B23: a) es conforme con: 1) los requisitos propios de la organización para su sistema de gestión ambiental; 2) los requisitos de esta Norma Internacional | D23: X | G23: Proceso de auditorias y procedimiento de auditorias
B24: b) está implementado y mantenido eficazmente. | D24: X | G24: Se hizo auditoria en el mes de septiembre de 2020
D25: =COUNTIF(D22:D24,"X") -> 2 | E25: =COUNTIF(E22:E24,"X") -> 0 | F25: =COUNTIF(F22:F24,"X") -> 0
B26: 9.2.2 Programa de auditoría interna | D26: =((D32*1)+(E32*0.5)+(F32*0))/5 -> 1
B27: La organización debe establecer, implementar y mantener uno o varios programas de auditoría que incluyan la frecuencia, los métodos, las responsabilidades, los requisitos de planificación y la elaboración de informes,cuando se establezca el programa de auditoria interna, la organización debe tener en cuenta la importancia ambiental de los procesos involucrados, los cambios que afectan a la organización y los resultados de las auditorias previas. La organización debe: | D27: X | G27: Programa de auditorias internas
B28: a) para cada auditoría, definir los criterios y el alcance de ésta; | D28: X | G28: Plan de auditorias
B29: c) seleccionar los auditores y llevar a cabo auditorías para asegurarse de la objetividad y la imparcialidad del proceso de auditoría; | D29: X | G29: Contratado externamente
B30: c) asegurarse de que los resultados de las auditorías se informan a la dirección pertinente; | D30: X | G30: Informe de auditoria
B31: conservar la información documentada como evidencia de la implementación del programa de auditoría y sus resultados. | D31: X | G31: Estan todos los registros
D32: =COUNTIF(D27:D31,"X") -> 5 | E32: =COUNTIF(E27:E31,"X") -> 0 | F32: =COUNTIF(F27:F31,"X") -> 0
B33: 9.3 Revisión por la dirección | D33: =((D49*1)+(E49*0.5)+(F49*0))/15 -> 0.6
B34: La alta dirección debe revisar el sistema de gestión ambiental de la organización a intervalos planificados, para asegurarse de su conveniencia, adecuación y eficacia continuas. | D34: X
B35: a) incluye consideraciones sobre el estado de las acciones desde anteriores revisiones por la dirección; | E35: X | G35: Informe RxD | H35: Falta la parte ambiental | I35: Actualizar o hacer un comité aparte | J35: Angelica Paez | K35: 44270
B36: b) incluye consideraciones sobre los cambios en: 1) las cuestiones externas e internas que sean pertinentes al sistema de gestión ambiental, 2) las necesidades y expectativas de las partes interesadas, incluidos los requisitos legales y otros requisitos. 3) sus aspectos ambientales significativos. 4) los riesgos y oportunidades | E36: X
B37: c) el grado en que se han logrado los objetivos ambientales; | E37: X
B38: d) la información sobre el desempeño ambiental de la organización, incluidas las tendencias relativas a: 1) no conformidades y acciones correctivas; 2) seguimiento y resultados de las mediciones; 3) cumplimiento de los requisitos legales y otros requisitos; 4) resultados de la auditoría; | E38: X
B39: e) adecuación de los recursos; | E39: X
B40: f) las comunicaciones pertinentes de las partes interesadas, incluidas las quejas; | E40: X
B41: g) las oporunidades de mejora continua; | E41: X
...

Sheet MEJORA
B2: 10. MEJORA | C2: NO APLICA | D2: COMPLETO | E2: PARCIAL | F2: NINGUNO | G2: QUÉ TIENE? | H2: QUE NOS FALTA | I2: ACCIONES | J2: RESPONSABLE | K2: FECHA
B3: 10.1 Generalidades | D3: =((D5*1)+(E5*0.5)+(F5*0))/1 -> 1
B4: La organización debe determinar y seleccionar las oportunidades de mejora (véanse 9.1, 9.2 y 9.3) e implementar las acciones necesarias para lograr los resultados previstos en su sistema de gestión ambiental. | D4: X | P4: =B3 -> 10.1 Generalidades | Q4: =D3 -> 1
D5: =COUNTIF(D4:D4,"X") -> 1 | E5: =COUNTIF(E4:E4,"X") -> 0 | F5: =COUNTIF(F4:F4,"X") -> 0 | P5: =B6 -> 10.2 No conformidad y acción correctiva | Q5: =D6 -> 0.5
B6: 10.2 No conformidad y acción correctiva | D6: =((D15*1)+(E15*0.5)+(F15*0))/7 -> 0.5 | P6: =B16 -> 10.3 Mejora continua | Q6: =D16 -> 0.5
B7: Cuando ocurra una no conformidad la organización debe: | P7: =B2 -> 10. MEJORA | Q7: =AVERAGE(Q4:Q6) -> 0.66666667
B8: a) reaccionar ante la no conformidad, cuando aplique: 1) tomar acciones para controlarla y corregirla; 2) hacer frente a las consecuencias incluida la mitigación de los impactos abientales adversos | E8: X
B9: b) evaluar la necesidad de acciones para eliminar las causas de la no conformidad, con el fin de que no vuelva a ocurrir ni ocurra en otra parte, mediante: 1) la revisión de la no conformidad; 2) la determinación de las causas de la no conformidad; 3) la determinación de si existen no conformidades similares, o que potencialmente podrían ocurrir; | E9: X | G9: Proceso de mejora y Procedimiento. Cultura de analisis a nivel Operativo | I9: Aplicar el proceso y procedimiento | J9: Lideres de Procesos | K9: Inmediato
B10: c) implementar cualquier acción necesaria; | E10: X
B11: d) revisar la eficacia de las acciones correctivas tomadas; | E11: X
B12: e) si es necesario, hacer cambios al sistema de gestión ambiental. | E12: X | G12: Gestion del cambio
B13: Las acciones correctivas deben ser adecuadas a los efectos de las no conformidades encontradas, incluidos los impactos ambientales | E13: X
B14: La organización debe conservar información documentada, como evidencia de: a) la naturaleza de las no conformidades y cualquier acción tomada posteriormente; y b) los resultados de cualquier acción correctiva. | E14: X
D15: =COUNTIF(D8:D14,"X") -> 0 | E15: =COUNTIF(E8:E14,"X") -> 7 | F15: =COUNTIF(F8:F14,"X") -> 0
B16: 10.3 Mejora continua | D16: =((D18*1)+(E18*0.5)+(F18*0))/1 -> 0.5
B17: La organización debe mejorar continuamente la conveniencia, adecuación y eficacia del sistema de gestión ambiental para mejorar el desempeño ambiental. | E17: X
D18: =COUNTIF(D17,"X") -> 0 | E18: =COUNTIF(E17,"X") -> 1 | F18: =COUNTIF(F17,"X") -> 0

Sheet PLAN DE ACCIÓN
